Traceback (most recent call last):
  File "/home/ubuntu/.local/lib/python3.10/site-packages/jupyter_cache/executors/utils.py", line 58, in single_nb_execution
    executenb(
  File "/home/ubuntu/.local/lib/python3.10/site-packages/nbclient/client.py", line 1305, in execute
    return NotebookClient(nb=nb, resources=resources, km=km, **kwargs).execute()
  File "/home/ubuntu/.local/lib/python3.10/site-packages/jupyter_core/utils/__init__.py", line 172, in wrapped
    return loop.run_until_complete(inner)
  File "/usr/lib/python3.10/asyncio/base_events.py", line 649, in run_until_complete
    return future.result()
  File "/home/ubuntu/.local/lib/python3.10/site-packages/nbclient/client.py", line 705, in async_execute
    await self.async_execute_cell(
  File "/home/ubuntu/.local/lib/python3.10/site-packages/nbclient/client.py", line 1058, in async_execute_cell
    await self._check_raise_for_error(cell, cell_index, exec_reply)
  File "/home/ubuntu/.local/lib/python3.10/site-packages/nbclient/client.py", line 914, in _check_raise_for_error
    raise CellExecutionError.from_cell_and_msg(cell, exec_reply_content)
nbclient.exceptions.CellExecutionError: An error occurred while executing the following cell:
------------------
flt = pe.MapNode(interface=fsl.FLIRT(cost='corratio', dof=12,
                                    searchr_x = [-90,90],
                                    searchr_y = [-90,90],
                                    searchr_z = [-90,90],
                                    interp = 'trilinear'), 
               name='example_func2standard',
               iterfield=['in_file'])

flt.inputs.reference = fsl.Info.standard_image('MNI152_T1_2mm_brain.nii.gz')
wf_first.connect(extract_ref, 'roi_file', flt, 'in_file')

convertxfm = pe.MapNode(interface=fsl.ConvertXFM(invert_xfm = True), 
                         name='convertxfm',
                         iterfield=['in_file'])
wf_first.connect(flt, 'out_matrix_file', convertxfm, 'in_file')
------------------


[0;31m---------------------------------------------------------------------------[0m
[0;31mKeyError[0m                                  Traceback (most recent call last)
File [0;32m~/.local/lib/python3.10/site-packages/nipype/interfaces/fsl/base.py:120[0m, in [0;36mInfo.standard_image[0;34m(img_name)[0m
[1;32m    119[0m [38;5;28;01mtry[39;00m:
[0;32m--> 120[0m     fsldir [38;5;241m=[39m [43mos[49m[38;5;241;43m.[39;49m[43menviron[49m[43m[[49m[38;5;124;43m"[39;49m[38;5;124;43mFSLDIR[39;49m[38;5;124;43m"[39;49m[43m][49m
[1;32m    121[0m [38;5;28;01mexcept[39;00m [38;5;167;01mKeyError[39;00m:

File [0;32m/usr/lib/python3.10/os.py:680[0m, in [0;36m_Environ.__getitem__[0;34m(self, key)[0m
[1;32m    678[0m [38;5;28;01mexcept[39;00m [38;5;167;01mKeyError[39;00m:
[1;32m    679[0m     [38;5;66;03m# raise KeyError with the original key value[39;00m
[0;32m--> 680[0m     [38;5;28;01mraise[39;00m [38;5;167;01mKeyError[39;00m(key) [38;5;28;01mfrom[39;00m [38;5;28mNone[39m
[1;32m    681[0m [38;5;28;01mreturn[39;00m [38;5;28mself[39m[38;5;241m.[39mdecodevalue(value)

[0;31mKeyError[0m: 'FSLDIR'

During handling of the above exception, another exception occurred:

[0;31mException[0m                                 Traceback (most recent call last)
Cell [0;32mIn[40], line 9[0m
[1;32m      1[0m flt [38;5;241m=[39m pe[38;5;241m.[39mMapNode(interface[38;5;241m=[39mfsl[38;5;241m.[39mFLIRT(cost[38;5;241m=[39m[38;5;124m'[39m[38;5;124mcorratio[39m[38;5;124m'[39m, dof[38;5;241m=[39m[38;5;241m12[39m,
[1;32m      2[0m                                     searchr_x [38;5;241m=[39m [[38;5;241m-[39m[38;5;241m90[39m,[38;5;241m90[39m],
[1;32m      3[0m                                     searchr_y [38;5;241m=[39m [[38;5;241m-[39m[38;5;241m90[39m,[38;5;241m90[39m],
[0;32m   (...)[0m
[1;32m      6[0m                name[38;5;241m=[39m[38;5;124m'[39m[38;5;124mexample_func2standard[39m[38;5;124m'[39m,
[1;32m      7[0m                iterfield[38;5;241m=[39m[[38;5;124m'[39m[38;5;124min_file[39m[38;5;124m'[39m])
[0;32m----> 9[0m flt[38;5;241m.[39minputs[38;5;241m.[39mreference [38;5;241m=[39m [43mfsl[49m[38;5;241;43m.[39;49m[43mInfo[49m[38;5;241;43m.[39;49m[43mstandard_image[49m[43m([49m[38;5;124;43m'[39;49m[38;5;124;43mMNI152_T1_2mm_brain.nii.gz[39;49m[38;5;124;43m'[39;49m[43m)[49m
[1;32m     10[0m wf_first[38;5;241m.[39mconnect(extract_ref, [38;5;124m'[39m[38;5;124mroi_file[39m[38;5;124m'[39m, flt, [38;5;124m'[39m[38;5;124min_file[39m[38;5;124m'[39m)
[1;32m     12[0m convertxfm [38;5;241m=[39m pe[38;5;241m.[39mMapNode(interface[38;5;241m=[39mfsl[38;5;241m.[39mConvertXFM(invert_xfm [38;5;241m=[39m [38;5;28;01mTrue[39;00m), 
[1;32m     13[0m                          name[38;5;241m=[39m[38;5;124m'[39m[38;5;124mconvertxfm[39m[38;5;124m'[39m,
[1;32m     14[0m                          iterfield[38;5;241m=[39m[[38;5;124m'[39m[38;5;124min_file[39m[38;5;124m'[39m])

File [0;32m~/.local/lib/python3.10/site-packages/nipype/interfaces/fsl/base.py:122[0m, in [0;36mInfo.standard_image[0;34m(img_name)[0m
[1;32m    120[0m     fsldir [38;5;241m=[39m os[38;5;241m.[39menviron[[38;5;124m"[39m[38;5;124mFSLDIR[39m[38;5;124m"[39m]
[1;32m    121[0m [38;5;28;01mexcept[39;00m [38;5;167;01mKeyError[39;00m:
[0;32m--> 122[0m     [38;5;28;01mraise[39;00m [38;5;167;01mException[39;00m([38;5;124m"[39m[38;5;124mFSL environment variables not set[39m[38;5;124m"[39m)
[1;32m    123[0m stdpath [38;5;241m=[39m os[38;5;241m.[39mpath[38;5;241m.[39mjoin(fsldir, [38;5;124m"[39m[38;5;124mdata[39m[38;5;124m"[39m, [38;5;124m"[39m[38;5;124mstandard[39m[38;5;124m"[39m)
[1;32m    124[0m [38;5;28;01mif[39;00m img_name [38;5;129;01mis[39;00m [38;5;28;01mNone[39;00m:

[0;31mException[0m: FSL environment variables not set

